Workbook

Sheet Índice
A1: CubeSat UD34 — Matrices, comparaciones y presupuestos (Práctica 3)
A2: Juan José Vásquez Urrutia · Jorge Andrés Urrea Franco — Diseño de Productos Electrónicos, UdeA, 2026-2
A4: Pestaña | B4: Contenido | C4: Sección del informe
A5: Requisitos | B5: Matriz de requisitos RF/RNF/RA/RN con origen, prioridad, método y criterio de aceptación. | C5: §2
A6: Especificaciones | B6: Especificaciones técnicas ET-01 a ET-29 con su requisito de origen. | C6: §3
A7: Trazabilidad | B7: Matriz requisito × especificación y conteo de cobertura por requisito (fórmulas). | C7: §3
A8: D1 Procesamiento | B8: Matriz ponderada: procesamiento centralizado vs. distribuido (fórmulas). | C8: §6.1
A9: D2 Enlace | B9: Matriz ponderada: un enlace UHF vs. UHF + banda S (fórmulas). | C9: §6.2
A10: D3 ADCS | B10: Matriz ponderada: actuadores de orientación, 3 alternativas (fórmulas). | C10: §6.3
A11: D4-D8 Cualitativas | B11: Comparación de la carga útil (D4) y decisiones de menor impacto (D5-D8). | C11: §6.4-6.5
A12: Supuestos órbita | B12: Parámetros de órbita y contacto que usan los presupuestos. | C12: §1.3, §10
A13: Presup. Potencia | B13: Potencia y energía por órbita, margen y casos de batería (fórmulas). | C13: §10.1
A14: Presup. Cómputo | B14: Uso de RAM, flash, SDRAM, eMMC, CPU y bus frente al margen del 50 % (fórmulas). | C14: §4.2
A15: Presup. Datos | B15: Volumen de datos, capacidad del enlace y almacenamiento (fórmulas). | C15: §10.3
... A17: Masa y Volumen | B17: Presupuesto de masa y altura del stack en Z (fórmulas). | C17: §10.5-10.6
A19: Cómo leer las celdas
A20: Texto azul | B20: Entrada: se puede cambiar (peso, calificación, potencia, pérdida, etc.).
A21: Texto negro | B21: Fórmula: se recalcula sola; no escribir encima.
A22: Relleno amarillo | B22: Dato que viene de otro cálculo (orbita.py, potencia.py, cobertura.py); si se rehace esa simulación, actualizarlo a mano.
A23: Verde / rojo | B23: Verificación automática: verde cumple el requisito o el margen, rojo no.
A25: Fuente del contenido: informe LaTeX v5 (latex_overleaf_v5/docs). Este archivo se genera con calculos/build_excel_v3.py; si cambian las tablas del informe, se puede volver a generar.

Sheet Requisitos
A1: Matriz de requisitos (§2)
A2: Método: I inspección, A análisis, D demostración, T ensayo.
A4: ID | B4: Tipo | C4: Requisito | D4: Origen / justificación | E4: Prioridad | F4: Método | G4: Criterio de aceptación
A5: RF-01 | B5: Funcional | C5: El satélite deberá adquirir imágenes de la superficie en al menos una banda roja y una banda de infrarrojo cercano, registradas sobre la misma escena. | D5: Misión: índices de vegetación (NDVI requiere rojo y NIR) \refr0 | E5: Alta | F5: T | G5: T: captura de un blanco con respuesta conocida en cada banda; se verifica que haya co-registro entre bandas.
A6: RF-02 | B6: Funcional | C6: El satélite deberá almacenar a bordo las imágenes y la telemetría hasta que se descarguen o hasta que tierra ordene borrarlas. | D6: Hay pocos contactos (2.4 pasos/día) y son cortos | E6: Alta | F6: D | G6: D: se captura, se apaga y enciende el sistema, y los archivos siguen íntegros (CRC).
A7: RF-03 | B7: Funcional | C7: El satélite deberá transmitir telemetría y productos de imagen a la estación de Medellín. | D7: Misión | E7: Alta | F7: T | G7: T: enlace en banco con atenuador calibrado a la pérdida del peor caso (\srefsec:balance-enlace).
A8: RF-04 | B8: Funcional | C8: El satélite deberá recibir, autenticar y ejecutar telecomandos desde tierra, incluidos los de reprogramar capturas y seleccionar regiones de interés (ROI). | D8: Operación remota; se evita ejecutar comandos no autorizados | E8: Alta | F8: D | G8: D: se rechazan comandos con autenticación inválida y se ejecutan los válidos.
A9: RF-05 | B9: Funcional | C9: El satélite deberá determinar su actitud respecto al marco orbital. | D9: La cámara y los paneles dependen de la orientación \refr0 | E9: Alta | F9: A+T | G9: A + T: estimador con datos de sensores en mesa de Helmholtz o simulación HIL.
A10: RF-06 | B10: Funcional | C10: El satélite deberá reducir su velocidad angular después del despliegue y orientar la cámara hacia nadir durante las capturas. | D10: Descripción del proyecto \refr0 (“reducir movimientos no deseados”, “orientar la cámara”) | E10: Alta | F10: A | G10: A: simulación del lazo con los parámetros reales de los actuadores.
A11: RF-07 | B11: Funcional | C11: El satélite deberá generar, almacenar, acondicionar y distribuir la energía eléctrica a todos los subsistemas. | D11: Descripción del proyecto \refr0; ECSS-E-ST-20C §5.2.2.1 \refr6 | E11: Alta | F11: T | G11: T: operación en banco con simulador solar/fuente con curva I-V.
A12: RF-08 | B12: Funcional | C12: El satélite deberá medir y reportar tensiones, corrientes y temperaturas de sus subsistemas. | D12: Descripción del proyecto \refr0 (telemetría) | E12: Alta | F12: D | G12: D: telemetría completa en la estación de prueba.
A13: RF-09 | B13: Funcional | C13: El satélite deberá detectar sobrecorrientes y fallas de software y recuperarse de forma autónoma a un modo seguro. | D13: Latch-up y SEU en componentes COTS; no hay operador permanente | E13: Alta | F13: T | G13: T: se inyecta una sobrecorriente o se bloquea el software, y el sistema vuelve a modo seguro sin intervención.
A14: RF-10 | B14: Funcional | C14: El satélite deberá desplegar su antena de forma autónoma después del tiempo mínimo exigido. | D14: Antena guardada durante el lanzamiento; CDS §2.4.4 \refr1 | E14: Alta | F14: T | G14: T: despliegue en banco activado por el temporizador.
A15: RF-11 | B15: Funcional | C15: El satélite deberá mantener una referencia de tiempo y ejecutar las capturas en una hora programada. | D15: La imagen se programa por posición orbital | E15: Media | F15: T | G15: T: error de disparo respecto a la hora programada (ver ET-24).
... A42: RN-12 | B42: Normativo | C42: Si se usan imanes permanentes, su campo no deberá superar 0.5 G sobre el campo terrestre fuera del volumen del satélite. | D42: CDS §2.1.8 \refr1 | E42: Baja | F42: A/T | G42: A/T (aplica a la rueda y a imanes pasivos).
A44: 38 requisitos: 11 funcionales, 10 no funcionales, 5 ambientales, 12 normativos.

Sheet Especificaciones
A1: Especificaciones técnicas (§3)
A2: La columna "Req." indica de qué requisito se deriva cada especificación.
A4: ID | B4: Req. | C4: Parámetro | D4: Valor / rango / tolerancia | E4: Unidad | F4: Fundamento | G4: Verificación
A5: ET-01 | B5: RF-01 | C5: Bandas espectrales (centro/ancho) | D5: Verde 560/35, Rojo 665/30, Borde rojo 705/15, NIR 842/115 | E5: nm | F5: Mismas bandas de Sentinel-2 (B3, B4, B5, B8) \refr11: permiten NDVI, GNDVI y NDRE, y comparar con datos públicos | G5: T: espectrofotómetro sobre el filtro
A6: ET-02 | B6: RNF-01 | C6: GSD a nadir | D6: 40 (≤ 50) | E6: m | F6: GSD = h·p/f = 550 km · 2.2 µm / 30 mm ≈ 40 m (f de ET-04) | G6: A + T (MTF)
A7: ET-03 | B7: RNF-01 | C7: Sensor de imagen | D7: CMOS monocromo, ≥ 2592 × 1944 px, pitch 2.2 µm, sensibilidad NIR mejorada, salida MIPI CSI-2 (clase onsemi AR0522 \refr19) | E7: — | F7: Formato 5 MP disponible en versión monocroma NIR; 10 bit de resolución radiométrica. Obturador rolling: ver R-08 | G7: I: hoja de datos
A8: ET-04 | B8: RNF-01 | C8: Óptica | D8: f = 30 mm ±1 mm, f/2.8, longitud ≤ 30 mm | E8: mm | F8: Con f/2.8 el radio de Airy a 842 nm es de 2.9 µm (1.3 px), aceptable para NIR | G8: T: MTF en banco
A9: ET-05 | B9: RNF-02 | C9: Ancho de franja | D9: 104 (≥ 90) | E9: km | F9: 2592 px × 40 m | G9: A
A10: ET-06 | B10: RF-01 | C10: Separación de bandas | D10: Filtro de 4 franjas sobre el sensor (pushframe): 486 filas por banda; un cuadro cada 2.78 s (≤ 2.78 s) | E10: — | F10: Con una sola óptica y un solo sensor se ahorra volumen (\srefsec:d4-tecnologia); el cuadro avanza 19.4 km | G10: A
A11: ET-07 | B11: RF-01 | C11: Tiempo de exposición máximo | D11: ≤ 2.9 | E11: ms | F11: Arrastre ≤ 0.5 px con v_suelo = 6.98 km/s | G11: A
A12: ET-08 | B12: RF-02, RNF-05 | C12: Buffer de imagen (RAM externa) | D12: ≥ 40 (se elige 64) | E12: MB | F12: Doble cuadro a 16 bit/px = 20.2 MB; con uso ≤ 50 % (RNF-05) se necesitan ≥ 40 MB | G12: A
A13: ET-09 | B13: RF-02, RNF-05 | C13: Almacenamiento masivo | D13: ≥ 3.7 (se elige eMMC industrial de 8) | E13: GB | F13: 10 pasadas × 183 MB = 1.83 GB, con uso ≤ 50 % | G13: A; T: escritura sostenida
A14: ET-10 | B14: RNF-03 | C14: Compresión a bordo | D14: Sin pérdidas, ≥ 1.8:1 (CCSDS 123.0-B o JPEG-LS) | E14: — | F14: Con 2:1, una ROI de 50 × 50 km en 4 bandas ocupa 3.9 MB | G14: T: con imágenes de prueba (TBD-02)
A15: ET-11 | B15: RF-03, RNF-03 | C15: Tasa del enlace descendente | D15: 9.6 (elev. < 15°) / 19.2 (elev. ≥ 15°), GMSK/GFSK + FEC | E15: kbps | F15: Balance de enlace \srefsec:balance-enlace: margen de +5.9 dB a 9.6 k y de +2.9 dB a 19.2 k a 10° | G15: T: BER en banco
... A34: ET-30 | B34: RN-01 | C34: Altura del stack dentro de la estructura | D34: ≤ 98.4 (se usan 89) | E34: mm | F34: Altura interior de la estructura ISISPACE \refr25; reparto por capas en \srefsec:volumen | G34: I: modelo 3D (P6)

Sheet Trazabilidad
A1: Matriz de trazabilidad requisito × especificación (§3)
A2: X = la especificación se deriva del requisito (columna "Req." de la tabla de especificaciones).
A4: Requisito | B4: Tipo | C4: ET-01 | D4: ET-02 | E4: ET-03 | F4: ET-04 | G4: ET-05 | H4: ET-06 | I4: ET-07 | J4: ET-08 | K4: ET-09 | L4: ET-10 | M4: ET-11 | N4: ET-12 | O4: ET-13 | P4: ET-14 | Q4: ET-15 | R4: ET-16 | S4: ET-17 | T4: ET-18 | U4: ET-19 | V4: ET-20 | W4: ET-21 | X4: ET-22 | Y4: ET-23 | Z4: ET-24 | AA4: ET-25 | AB4: ET-26 | AC4: ET-27 | AD4: ET-28 | AE4: ET-29 | AF4: ET-30 | AG4: N.º de ET | AH4: Cobertura
A5: RF-01 | B5: Funcional | C5: X | H5: X | I5: X | AG5: =COUNTIF(C5:AF5,"X") -> 3 | AH5: =IF(AG5>0,"Cubierto por ET","Verificación directa / regla de diseño") -> Cubierto por ET
A6: RF-02 | B6: Funcional | J6: X | K6: X | AG6: =COUNTIF(C6:AF6,"X") -> 2 | AH6: =IF(AG6>0,"Cubierto por ET","Verificación directa / regla de diseño") -> Cubierto por ET
A7: RF-03 | B7: Funcional | M7: X | N7: X | AG7: =COUNTIF(C7:AF7,"X") -> 2 | AH7: =IF(AG7>0,"Cubierto por ET","Verificación directa / regla de diseño") -> Cubierto por ET
A8: RF-04 | B8: Funcional | O8: X | AG8: =COUNTIF(C8:AF8,"X") -> 1 | AH8: =IF(AG8>0,"Cubierto por ET","Verificación directa / regla de diseño") -> Cubierto por ET
A9: RF-05 | B9: Funcional | Q9: X | AG9: =COUNTIF(C9:AF9,"X") -> 1 | AH9: =IF(AG9>0,"Cubierto por ET","Verificación directa / regla de diseño") -> Cubierto por ET
A10: RF-06 | B10: Funcional | R10: X | S10: X | AG10: =COUNTIF(C10:AF10,"X") -> 2 | AH10: =IF(AG10>0,"Cubierto por ET","Verificación directa / regla de diseño") -> Cubierto por ET
A11: RF-07 | B11: Funcional | V11: X | W11: X | AE11: X | AG11: =COUNTIF(C11:AF11,"X") -> 3 | AH11: =IF(AG11>0,"Cubierto por ET","Verificación directa / regla de diseño") -> Cubierto por ET
A12: RF-08 | B12: Funcional | X12: X | AG12: =COUNTIF(C12:AF12,"X") -> 1 | AH12: =IF(AG12>0,"Cubierto por ET","Verificación directa / regla de diseño") -> Cubierto por ET
A13: RF-09 | B13: Funcional | X13: X | AG13: =COUNTIF(C13:AF13,"X") -> 1 | AH13: =IF(AG13>0,"Cubierto por ET","Verificación directa / regla de diseño") -> Cubierto por ET
A14: RF-10 | B14: Funcional | AD14: X | AG14: =COUNTIF(C14:AF14,"X") -> 1 | AH14: =IF(AG14>0,"Cubierto por ET","Verificación directa / regla de diseño") -> Cubierto por ET
A15: RF-11 | B15: Funcional | Z15: X | AG15: =COUNTIF(C15:AF15,"X") -> 1 | AH15: =IF(AG15>0,"Cubierto por ET","Verificación directa / regla de diseño") -> Cubierto por ET
A16: RNF-01 | B16: No funcional | D16: X | E16: X | F16: X | AG16: =COUNTIF(C16:AF16,"X") -> 3 | AH16: =IF(AG16>0,"Cubierto por ET","Verificación directa / regla de diseño") -> Cubierto por ET
A17: RNF-02 | B17: No funcional | G17: X | AG17: =COUNTIF(C17:AF17,"X") -> 1 | AH17: =IF(AG17>0,"Cubierto por ET","Verificación directa / regla de diseño") -> Cubierto por ET
A18: RNF-03 | B18: No funcional | L18: X | M18: X | AG18: =COUNTIF(C18:AF18,"X") -> 2 | AH18: =IF(AG18>0,"Cubierto por ET","Verificación directa / regla de diseño") -> Cubierto por ET
A19: RNF-04 | B19: No funcional | T19: X | U19: X | AE19: X | AG19: =COUNTIF(C19:AF19,"X") -> 3 | AH19: =IF(AG19>0,"Cubierto por ET","Verificación directa / regla de diseño") -> Cubierto por ET
A20: RNF-05 | B20: No funcional | J20: X | K20: X | AG20: =COUNTIF(C20:AF20,"X") -> 2 | AH20: =IF(AG20>0,"Cubierto por ET","Verificación directa / regla de diseño") -> Cubierto por ET
A21: RNF-06 | B21: No funcional | AA21: X | AG21: =COUNTIF(C21:AF21,"X") -> 1 | AH21: =IF(AG21>0,"Cubierto por ET","Verificación directa / regla de diseño") -> Cubierto por ET
A22: RNF-07 | B22: No funcional | P22: X | Q22: X | AG22: =COUNTIF(C22:AF22,"X") -> 2 | AH22: =IF(AG22>0,"Cubierto por ET","Verificación directa / regla de diseño") -> Cubierto por ET
A23: RNF-08 | B23: No funcional | AB23: X | AG23: =COUNTIF(C23:AF23,"X") -> 1 | AH23: =IF(AG23>0,"Cubierto por ET","Verificación directa / regla de diseño") -> Cubierto por ET
A24: RNF-09 | B24: No funcional | AG24: =COUNTIF(C24:AF24,"X") -> 0 | AH24: =IF(AG24>0,"Cubierto por ET","Verificación directa / regla de diseño") -> Verificación directa / regla de diseño
A25: RNF-10 | B25: No funcional | AG25: =COUNTIF(C25:AF25,"X") -> 0 | AH25: =IF(AG25>0,"Cubierto por ET","Verificación directa / regla de diseño") -> Verificación directa / regla de diseño
A26: RA-01 | B26: Ambiental | Y26: X | AG26: =COUNTIF(C26:AF26,"X") -> 1 | AH26: =IF(AG26>0,"Cubierto por ET","Verificación directa / regla de diseño") -> Cubierto por ET
A27: RA-02 | B27: Ambiental | AG27: =COUNTIF(C27:AF27,"X") -> 0 | AH27: =IF(AG27>0,"Cubierto por ET","Verificación directa / regla de diseño") -> Verificación directa / regla de diseño
A28: RA-03 | B28: Ambiental | X28: X | AG28: =COUNTIF(C28:AF28,"X") -> 1 | AH28: =IF(AG28>0,"Cubierto por ET","Verificación directa / regla de diseño") -> Cubierto por ET
A29: RA-04 | B29: Ambiental | AG29: =COUNTIF(C29:AF29,"X") -> 0 | AH29: =IF(AG29>0,"Cubierto por ET","Verificación directa / regla de diseño") -> Verificación directa / regla de diseño
A30: RA-05 | B30: Ambiental | AG30: =COUNTIF(C30:AF30,"X") -> 0 | AH30: =IF(AG30>0,"Cubierto por ET","Verificación directa / regla de diseño") -> Verificación directa / regla de diseño
A31: RN-01 | B31: Normativo | AF31: X | AG31: =COUNTIF(C31:AF31,"X") -> 1 | AH31: =IF(AG31>0,"Cubierto por ET","Verificación directa / regla de diseño") -> Cubierto por ET
A32: RN-02 | B32: Normativo | AB32: X | AG32: =COUNTIF(C32:AF32,"X") -> 1 | AH32: =IF(AG32>0,"Cubierto por ET","Verificación directa / regla de diseño") -> Cubierto por ET
A33: RN-03 | B33: Normativo | AG33: =COUNTIF(C33:AF33,"X") -> 0 | AH33: =IF(AG33>0,"Cubierto por ET","Verificación directa / regla de diseño") -> Verificación directa / regla de diseño
A34: RN-04 | B34: Normativo | AC34: X | AG34: =COUNTIF(C34:AF34,"X") -> 1 | AH34: =IF(AG34>0,"Cubierto por ET","Verificación directa / regla de diseño") -> Cubierto por ET
A35: RN-05 | B35: Normativo | AC35: X | AG35: =COUNTIF(C35:AF35,"X") -> 1 | AH35: =IF(AG35>0,"Cubierto por ET","Verificación directa / regla de diseño") -> Cubierto por ET
A36: RN-06 | B36: Normativo | AD36: X | AG36: =COUNTIF(C36:AF36,"X") -> 1 | AH36: =IF(AG36>0,"Cubierto por ET","Verificación directa / regla de diseño") -> Cubierto por ET
A37: RN-07 | B37: Normativo | AG37: =COUNTIF(C37:AF37,"X") -> 0 | AH37: =IF(AG37>0,"Cubierto por ET","Verificación directa / regla de diseño") -> Verificación directa / regla de diseño
A38: RN-08 | B38: Normativo | AG38: =COUNTIF(C38:AF38,"X") -> 0 | AH38: =IF(AG38>0,"Cubierto por ET","Verificación directa / regla de diseño") -> Verificación directa / regla de diseño
A39: RN-09 | B39: Normativo | AG39: =COUNTIF(C39:AF39,"X") -> 0 | AH39: =IF(AG39>0,"Cubierto por ET","Verificación directa / regla de diseño") -> Verificación directa / regla de diseño
A40: RN-10 | B40: Normativo | AG40: =COUNTIF(C40:AF40,"X") -> 0 | AH40: =IF(AG40>0,"Cubierto por ET","Verificación directa / regla de diseño") -> Verificación directa / regla de diseño
A41: RN-11 | B41: Normativo | AG41: =COUNTIF(C41:AF41,"X") -> 0 | AH41: =IF(AG41>0,"Cubierto por ET","Verificación directa / regla de diseño") -> Verificación directa / regla de diseño
...

Sheet D1 Procesamiento
A1: D1 Procesamiento — matriz ponderada (§6.1)
A2: Puntaje = Σ(peso × calificación) / 100. Calificación de 1 (malo) a 5 (excelente).
A4: Criterio | B4: Peso | C4: A | D4: B | E4: Justificación
A5: Energía | B5: 25 | C5: 2 | D5: 5 | E5: A deja encendidos todo el tiempo un M7 de 600 MHz + SDRAM (≈ 0.3–0.4 W). B lo hace con ≈ 0.1 W. La diferencia ( 0.25 W ≈ 0.4 Wh/órbita) es mayor que todo el margen de energía (0.2 Wh).
A6: Procesamiento e interfaces | B6: 20 | C6: 4 | D6: 4 | E6: Los dos cumplen: la carga pesada es la misma, solo cambia dónde corre.
A7: Masa y volumen | B7: 15 | C7: 4 | D7: 3 | E7: B agrega un procesador. Pero el sensor ya necesita su propia tarjeta junto a la óptica, así que el procesador se monta en esa misma tarjeta y el costo en volumen es bajo.
A8: Complejidad | B8: 15 | C8: 4 | D8: 3 | E8: B necesita un protocolo entre procesadores (sobre el mismo CAN que ya existe).
A9: Riesgo y robustez | B9: 15 | C9: 2 | D9: 4 | E9: En A, un SEU en la SDRAM o en la cadena de imagen puede tumbar el TT&C (punto único de falla). En B, una falla de la carga útil deja vivo el OBC.
A10: Facilidad de prueba | B10: 10 | C10: 3 | D10: 4 | E10: En B la carga útil se prueba por separado.
A11: Total ponderado | B11: =SUM(B5:B10) -> 100 | C11: =SUMPRODUCT($B$5:$B$10,C5:C10)/100 -> 3.1 | D11: =SUMPRODUCT($B$5:$B$10,D5:D10)/100 -> 3.95
A12: Suma de pesos = 100 | B12: =IF(B11=100,"OK","NO: revisar pesos") -> OK
A13: Mayor puntaje | B13: =INDEX($C$4:$D$4,MATCH(MAX(C11:D11),C11:D11,0)) -> B
A15: Alternativas
A16: A. Centralizado | B16: Un solo procesador de alto desempeño (Cortex-M7 con CSI-2 y SDRAM), siempre encendido, que hace las funciones del OBC, del ADCS, de las comunicaciones y de la carga útil.
A17: B. Distribuido | B17: Un OBC de bajo consumo siempre encendido y un procesador de carga útil que el EPS enciende solo durante la captura y la descarga.
A19: Decisión | B19: B. El argumento principal es la energía: con A no se cumple RNF-04. Limitación: hay dos firmwares y una interfaz más que verificar.

Sheet D2 Enlace
A1: D2 Enlace — matriz ponderada (§6.2)
A2: Puntaje = Σ(peso × calificación) / 100. Calificación de 1 (malo) a 5 (excelente).
A4: Criterio | B4: Peso | C4: A | D4: B | E4: Justificación
A5: Capacidad de datos | B5: 25 | C5: 2 | D5: 5 | E5: A: 1.15 MB/día (1 ROI por ciclo). B: > 50 MB por paso (la pasada completa).
A6: Energía | B6: 20 | C6: 5 | D6: 3 | E6: B: 13 W × 6.6 min ≈ 1.4 Wh por paso. Se puede con la batería, pero además exige ≥ 7 V y la batería 2S trabaja entre 6.4 y 8.4 V (se necesitaría un elevador).
A7: Volumen y masa | B7: 20 | C7: 5 | D7: 1 | E7: B suma 14.5 mm de stack + un parche en −Z que compite con la óptica. Solo quedan unos 9 mm libres, así que no cabe sin quitar otra cosa.
A8: Complejidad y costo (incluye estación) | B8: 15 | C8: 5 | D8: 2 | E8: B necesita una parábola con seguimiento de ≥ 1.2 m en Medellín y una interfaz LVDS. A funciona con una Yagi, un rotor y un SDR.
A9: Regulación | B9: 10 | C9: 4 | D9: 3 | E9: A: banda de aficionados, datos abiertos (compatible con RN-10). B: 2200–2290 MHz es de investigación espacial/EESS y requiere registro ante la UIT sin la vía de aficionados.
A10: Riesgo | B10: 10 | C10: 4 | D10: 3 | E10: B tiene más potencia disipada y más interfaces.
A11: Total ponderado | B11: =SUM(B5:B10) -> 100 | C11: =SUMPRODUCT($B$5:$B$10,C5:C10)/100 -> 4.05 | D11: =SUMPRODUCT($B$5:$B$10,D5:D10)/100 -> 2.95
A12: Suma de pesos = 100 | B12: =IF(B11=100,"OK","NO: revisar pesos") -> OK
A13: Mayor puntaje | B13: =INDEX($C$4:$D$4,MATCH(MAX(C11:D11),C11:D11,0)) -> A
A15: Alternativas
A16: A. Un enlace UHF | B16: Clase GomSpace AX100 [R12]: 24.5 g, recepción 0.18 W, transmisión 2.64 W, hasta 38.4 kbps. Telemetría, comandos y datos; se baja solo la ROI y la vista previa.
A17: B. UHF + banda S | B17: UHF para telemetría y comandos + transmisor en banda S clase ISIS TXS [R13]: 132 g, 13 W al transmitir, hasta 4.3 Mbps, 7-20 V, 98.8 × 93.3 × 14.5 mm.
A19: Decisión | B19: A. Limitación: se baja una muestra de cada pasada (ROI y vista previa), no la pasada completa; los datos crudos quedan a bordo (8 GB). Si en P6 hay más volumen, B es la mejora natural.

Sheet D3 ADCS
A1: D3 ADCS — matriz ponderada (§6.3)
A2: Puntaje = Σ(peso × calificación) / 100. Calificación de 1 (malo) a 5 (excelente).
A4: Criterio | B4: Peso | C4: A | D4: B | E4: C | F4: Justificación
A5: Precisión frente a ≤ 4° | B5: 30 | C5: 1 | D5: 4 | E5: 5 | F5: A: ±10–15° (solo se controlan 2 ejes a la vez). B: ±2–5° con la rigidez giroscópica. C: < 1°.
A6: Energía | B6: 25 | C6: 5 | D6: 3 | E6: 1 | F6: +0.3 W (B) o +0.9 W (C). Con C el consumo sube a 2.7 Wh/órbita y supera la generación.
A7: Masa y volumen | B7: 20 | C7: 5 | D7: 4 | E7: 1 | F7: B: 60 g, al lado del tubo de la óptica. C: 180 g y 3 ejes.
A8: Complejidad | B8: 15 | C8: 5 | D8: 3 | E8: 2
A9: Riesgo | B9: 10 | C9: 4 | D9: 3 | E9: 2 | F9: Partes móviles.
A10: Total ponderado | B10: =SUM(B5:B9) -> 100 | C10: =SUMPRODUCT($B$5:$B$9,C5:C9)/100 -> 3.7 | D10: =SUMPRODUCT($B$5:$B$9,D5:D9)/100 -> 3.5 | E10: =SUMPRODUCT($B$5:$B$9,E5:E9)/100 -> 2.45
A11: Suma de pesos = 100 | B11: =IF(B10=100,"OK","NO: revisar pesos") -> OK
A12: Mayor puntaje | B12: =INDEX($C$4:$E$4,MATCH(MAX(C10:E10),C10:E10,0)) -> A
A14: Alternativas
A15: A. Solo magnetorquers | B15: 3 magnetorquers (B-dot y apuntamiento magnético).
A16: B. Magnetorquers + 1 rueda | B16: 3 magnetorquers y 1 rueda de momento en pitch (clase CubeSpace CW0017 [R15]: 60 g, 1.77 mNms, 0.3 W).
A17: C. Magnetorquers + 3 ruedas | B17: 3 magnetorquers y 3 ruedas de reacción.
A19: Decisión | B19: B, aunque A tiene más puntaje: A no cumple RNF-07 (apuntamiento ≤ 4°), que es esencial, así que se descarta antes de ponderar. El puntaje apoya la decisión pero no reemplaza esa verificación. Limitación: roll y yaw dependen de los magnetorquers (riesgo R-02).

Sheet D4-D8 Cualitativas
A1: Comparaciones cualitativas (§6.4 y §6.5)
A2: Decisiones con una alternativa claramente mejor; se justifican sin matriz ponderada.
A3: D4 — Tecnología de la carga útil multiespectral
A4: Opción | B4: Ventajas | C4: Desventajas | D4: Decisión
A5: A. Dos cámaras (RGB Bayer + mono NIR) | B5: Captura simultánea, SW simple | C5: Dos ópticas: 2× volumen en −Z; dos puertos CSI; el filtro Bayer tiene bandas anchas y sin borde rojo | D5: —
A6: B. Un sensor mono + filtro de 4 franjas (pushframe) | B6: Una sola óptica y un solo CSI-2, bandas definidas por diseño; mismo principio que SuperDove de Planet \refr23 | C6: Requiere actitud estable durante toda la captura ( 70 s) y co-registro en tierra; el filtro es una pieza a medida (TBD-03); obturador rolling (R-08) | D6: Se elige
A7: C. Sensor con mosaico espectral por píxel | B7: Una óptica, captura simultánea | C7: Poca oferta, pierde resolución (4 px por muestra), costoso | D7: —
A8: D. Cámara multiespectral comercial completa (p. ej. Simera MultiScape50) | B8: Producto probado en vuelo, 8 bandas, 30 m a 500 km \refr24 | C8: Ocupa 1U por sí sola: no deja espacio para EPS, OBC ni batería; costo alto | D8: —
A10: D5-D8 — Decisiones de menor impacto
A11: Decisión | B11: Alternativas | C11: Selección y razón
A12: D5 Arquitectura de potencia | B12: (a) Transferencia directa (DET) con bus regulado; (b) MPPT + bus de batería sin regular + convertidores POL | C12: (b): la tensión del panel (2 celdas ≈ 4.8 V) no coincide con la de la batería 2S (6.4–8.4 V), así que DET no sirve sin cambiar el arreglo y los cargadores deben ser elevadores o buck-boost (ET-29); el MPPT recupera la pérdida por temperatura y ángulo. Unir ±X y ±Y por diodo usa 2 cargadores, porque caras opuestas nunca están iluminadas a la vez.
A13: D6 Bus interno | B13: (a) I2C compartido; (b) CAN entre tarjetas + I2C/SPI solo dentro de cada tarjeta | C13: (b): un esclavo I2C colgado bloquea todo el bus (modo de falla conocido en CubeSats); CAN es diferencial, multimaestro y con CRC, y el transceptor y la rueda ya lo soportan.
A14: D7 División en PCBs | B14: (a) 4 tarjetas (EPS, OBC/ADCS, COM, carga útil); (b) 3 tarjetas (EPS, OBC/ADCS/COM, carga útil) | C14: (b): con 4 tarjetas, el stack mide 104 mm y no cabe en los 98.4 mm interiores. El transceptor es un módulo hija de 6.5 mm que va sobre la tarjeta del OBC (\srefsec:arquitectura-seleccionada). Tampoco se usan 2 tarjetas (el mínimo del proyecto \refr0): las líneas MIPI y la SDRAM deben quedar pegadas al sensor, bajo la óptica, lejos del OBC.
A15: D8 Paneles solares | B15: (a) Fijos en las 4 caras laterales; (b) desplegables | C15: (a): con paneles fijos ya se cumple RNF-04 (margen del 11 % en el peor caso). Los desplegables agregarían bisagras y otro mecanismo de retención con sus 3 inhibidores (RN-05), el riesgo de que no abran y un cambio en la inercia que controla el ADCS. Si en P6 se necesita más energía, son la mejora natural.

Sheet Supuestos órbita
A1: Supuestos de órbita y contacto
A2: Datos de simulación (orbita.py, cobertura.py). Las hojas de presupuestos toman los valores de aquí.
A4: Parámetro | B4: Valor | C4: Unidad | D4: Fuente
A5: Periodo orbital T_orb | B5: 95.65 | C5: min | D5: SSO 550 km (orbita.py)
A6: Órbitas por día | B6: =1440/B5 -> 15.054888 | C6: órb./día | D6: fórmula
A7: Eclipse, peor caso (β = 15°) | B7: 35.2 | C7: min | D7: sombra cilíndrica (orbita.py)
A8: Contacto total sobre Medellín | B8: 15.6 | C8: min/día | D8: elevación ≥ 10°, simulación de 30 días (orbita.py)
A9: Pasos por día | B9: 2.37 | C9: pasos/día | D9: elevación ≥ 10° (orbita.py)
A10: Duración máxima de un paso | B10: 7.9 | C10: min | D10: paso cenital (orbita.py)
A11: Fracción del contacto sobre 15° de elevación | B11: 0.71 | C11: — | D11: orbita.py (11.1 de 15.6 min)
A12: Días entre oportunidades de imagen | B12: 5.5 | C12: días | D12: 33 días en 180 (cobertura.py)
A13: Altura orbital | B13: 550 | C13: km | D13: guía de la práctica [R0]

Sheet Presup. Potencia
A1: Presupuesto de potencia y energía por órbita (§10.1)
A2: Energía = P nominal × ciclo × T_orb. Consumo total = Σ energía / η + autoconsumo del EPS.
A4: T_orb (h) | B4: ='Supuestos órbita'!$B$5/60 -> 1.5941667
A5: Eficiencia de conversión η | B5: 0.88
A6: Autoconsumo del EPS (W) | B6: 0.1
A7: Fracción del paso transmitiendo | B7: 0.6
A8: Carga útil encendida por oportunidad (min) | B8: 10
A10: Subsistema | B10: P nominal (W) | C10: P máxima (W) | D10: Ciclo de actividad | E10: Energía (Wh/órbita) | F10: % del consumo | G10: Fuente / nota
A11: OBC (Cortex-M33/M4F + FRAM + NOR) | B11: 0.1 | C11: 0.2 | D11: 1 | E11: =B11*D11*$B$4 -> 0.15941667 | F11: =E11/$B$5/$E$21 -> 0.11270063 | G11: Clase STM32U575 [R21], ≈ 0.1 W con sus memorias
A12: Transceptor UHF — Rx | B12: 0.18 | C12: 0.4 | D12: 1 | E12: =B12*D12*$B$4 -> 0.28695 | F12: =E12/$B$5/$E$21 -> 0.20286114 | G12: AX100: 55 mA @ 3.3 V [R12]
A13: Transceptor UHF — Tx (1 W RF) | B13: 2.64 | C13: 3.3 | D13: =('Supuestos órbita'!$B$8*$B$7/'Supuestos órbita'!$B$6)/'Supuestos órbita'!$B$5 -> 0.0065 | E13: =B13*D13*$B$4 -> 0.0273559 | F13: =E13/$B$5/$E$21 -> 0.019339429 | G13: AX100: 800 mA @ 3.3 V [R12]; ciclo = contacto × fracción en Tx / órbitas por día / T_orb
A14: ADCS — sensores | B14: 0.1 | C14: 0.15 | D14: 1 | E14: =B14*D14*$B$4 -> 0.15941667 | F14: =E14/$B$5/$E$21 -> 0.11270063 | G14: RM3100 (~1 mW) [R27] + ISM330DHCX (~4 mW) [R28] + fotodiodos y ADC; 0.1 W con margen
A15: ADCS — 3 magnetorquers | B15: 0.2 | C15: 0.6 | D15: 0.5 | E15: =B15*D15*$B$4 -> 0.15941667 | F15: =E15/$B$5/$E$21 -> 0.11270063 | G15: EXA MT01 [R14]
A16: ADCS — rueda de momento | B16: 0.3 | C16: 0.85 | D16: 1 | E16: =B16*D16*$B$4 -> 0.47825 | F16: =E16/$B$5/$E$21 -> 0.3381019 | G16: CubeSpace CW0017 [R15]: 0.3 W estable, 0.85 W pico
A17: Carga útil (sensor + PPU + SDRAM + eMMC) | B17: 1.7 | C17: 2.5 | D17: =($B$8/('Supuestos órbita'!$B$12*'Supuestos órbita'!$B$6))/'Supuestos órbita'!$B$5 -> 0.0012626263 | E17: =B17*D17*$B$4 -> 0.0034218224 | F17: =E17/$B$5/$E$21 -> 0.0024190792 | G17: AR0522 [R19] + i.MX RT1170 [R16]; ciclo = min encendida / (días entre oportunidades × órbitas/día) / T_orb
A18: Calefactor de batería (nominal) | B18: 1 | C18: 1 | D18: 0 | E18: =B18*D18*$B$4 -> 0 | F18: =E18/$B$5/$E$21 -> 0 | G18: ET-23; solo entra en el peor caso (ver abajo)
A19: Suma de cargas | E19: =SUM(E11:E18) -> 1.2742277
A20: Pérdidas de conversión + autoconsumo EPS (incluye su MCU) | E20: =E19/$B$5-E19+$B$6*$B$4 -> 0.33317499
A21: Consumo total por órbita | E21: =E19+E20 -> 1.6074027
A23: Generación solar (nadir, 4 caras) | E23: Generación (Wh/órbita) | F23: Margen | G23: Verificación RNF-04 (margen ≥ 10 %)
A24: β = 15° (peor caso) | E24: 1.81 | F24: =(E24-$E$21)/E24 -> 0.1119322 | G24: =IF(F24>=0.1,"Cumple","NO cumple") -> Cumple
A25: β = 22° | E25: 2 | F25: =(E25-$E$21)/E25 -> 0.19629864 | G25: =IF(F25>=0.1,"Cumple","NO cumple") -> Cumple
A26: β = 30° | E26: 2.2 | F26: =(E26-$E$21)/E26 -> 0.2693624 | G26: =IF(F26>=0.1,"Cumple","NO cumple") -> Cumple
A27: La generación (amarillo) sale de potencia.py: 2 celdas AZUR 3G30 de 30.18 cm² por cara, η = 28 %, pérdidas 0.83, integrando el ángulo del Sol en la órbita. Si cambian celdas o área, correr potencia.py y actualizar estas tres celdas.
A29: Casos que definen la batería | B29: Valor | C29: Unidad | G29: Nota
A30: Celdas en serie | B30: 2 | C30: — | G30: entrada
A31: Tensión nominal por celda | B31: 3.6 | C31: V | G31: entrada
A32: Capacidad de la celda | B32: 2.6 | C32: Ah | G32: entrada — clase Panasonic NCR18650B [R8]
A33: Energía de la batería | B33: =B30*B31*B32 -> 18.72 | C33: Wh
A34: Energía en eclipse (nominal) | B34: =($E$21/$B$4)*'Supuestos órbita'!$B$7/60 -> 0.59153764 | C34: Wh
A35: Profundidad de descarga en eclipse | B35: =B34/B33 -> 0.031599233 | C35: —
A36: Consumo en la peor órbita | B36: =$E$21+($B$13*'Supuestos órbita'!$B$10/60+$B$17*$B$8/60+$B$18*0.2*'Supuestos órbita'!$B$7/60)/$B$5 -> 2.4577057 | C36: Wh | G36: paso completo en Tx + carga útil + calefactor el 20 % del eclipse
A37: Déficit en la peor órbita (vs. β = 15°) | B37: =B36-$E$24 -> 0.64770575 | C37: Wh | G37: lo cubre la batería; se recupera en las órbitas siguientes
A38: Profundidad de descarga en la peor órbita | B38: =(B34+B36-$E$21)/B33 -> 0.077021403 | C38: —
A39: Potencia en modo seguro | B39: =($B$11+$B$12+$B$14+$B$15*$D$15)/$B$5+$B$6 -> 0.64545455 | C39: W | G39: OBC + Rx + sensores + magnetorquers; sin rueda ni carga útil
A40: Energía por órbita en modo seguro | B40: =B39*$B$4 -> 1.0289621 | C40: Wh | G40: con el satélite girando se generan ≈ 1.94 Wh/órbita (potencia.py)
A41: Autonomía solo con batería (DoD 80 %) | B41: =0.8*B33/B39 -> 23.202254 | C41: h
A43: La batería no se dimensiona por capacidad (la descarga por ciclo es pequeña) sino por la tensión del bus 2S (motor de la rueda ≥ 6.4 V [R15]), la corriente de pico y la herencia de vuelo de la celda.

Sheet Presup. Datos
A1: Presupuesto de datos, enlace y almacenamiento (§10.3)
A2: Todo se recalcula a partir de las celdas azules.
A4: Cámara y adquisición | B4: Valor | C4: Unidad | E4: Nota
A5: Píxeles por fila (nx) | B5: 2592 | C5: px | E5: AR0522 [R19]
A6: Filas (ny) | B6: 1944 | C6: px
A7: Bits por píxel | B7: 10 | C7: bit
A8: Bandas (franjas del filtro) | B8: 4 | C8: — | E8: ET-01, ET-06
A9: GSD | B9: 40 | C9: m | E9: ET-02
A10: Recorrido N-S sobre la zona cafetera | B10: 470 | C10: km | E10: S-04 (1.5-5.8° N aprox.)
A11: Tamaño de un cuadro | B11: =B5*B6*B7/8/1000000 -> 6.29856 | C11: MB
A12: Avance por franja de banda | B12: =(B6/B8)*B9/1000 -> 19.44 | C12: km | E12: un cuadro cada franja (pushframe)
A13: Cuadros por oportunidad | B13: =CEILING((B10+B6*B9/1000)/B12,1) -> 29 | C13: cuadros
A14: Datos crudos por oportunidad | B14: =B13*B11 -> 182.65824 | C14: MB
A15: Compresión sin pérdidas | B15: 2 | C15: x:1 | E15: TBD-02 (se exige ≥ 1.8:1)
A16: Lado de la ROI | B16: 50 | C16: km | E16: RNF-03
A17: Decimación de la vista previa | B17: 16 | C17: × | E17: por lado
A19: Capacidad del enlace | B19: Valor | C19: Unidad | E19: Nota
A20: Eficiencia de protocolo (tramas, FEC, reintentos) | B20: 0.75 | C20: —
A21: Fracción de pasos que se usan | B21: 0.8 | C21: —
A22: Capacidad a 9.6 kbps | B22: =9600*'Supuestos órbita'!$B$8*60*B20*B21/8/1000000 -> 0.67392 | C22: MB/día
A23: Capacidad a 19.2 kbps | B23: =19200*'Supuestos órbita'!$B$8*60*B20*B21/8/1000000 -> 1.34784 | C23: MB/día
A24: Capacidad con tasa adaptativa | B24: ='Supuestos órbita'!$B$11*B23+(1-'Supuestos órbita'!$B$11)*B22 -> 1.1524032 | C24: MB/día | E24: 19.2 kbps sobre 15° de elevación, 9.6 kbps por debajo
A26: Fuente de datos (a bajar) | B26: Por adquisición (MB) | C26: Unidad | D26: Por día (MB/día) | E26: Nota
A27: Vista previa de la pasada | B27: =B14/(B17^2)/B15 -> 0.35675438 | C27: MB | D27: =B27/'Supuestos órbita'!$B$12 -> 0.064864432 | E27: 1 por pasada
A28: ROI sin pérdidas, todas las bandas | B28: =(B16*1000/B9)^2*B8*B7/8/1000000/B15 -> 3.90625 | C28: MB | D28: =B28/'Supuestos órbita'!$B$12 -> 0.71022727 | E28: 1 por pasada
A29: Telemetría de misión (64 B/min) | B29: =64*1440/1000000 -> 0.09216 | C29: MB/día | D29: =B29 -> 0.09216 | E29: continua
A30: Total a bajar | D30: =SUM(D27:D29) -> 0.8672517
A31: Margen del enlace (capacidad adaptativa vs. total) | D31: =(B24-D30)/B24 -> 0.24744074 | E31: =IF(D31>=0,"Cumple RNF-03","NO cumple RNF-03: bajar la ROI o subir la compresión") -> Cumple RNF-03
A33: Almacenamiento y memoria | B33: Valor | C33: Unidad | E33: Nota
A34: Pasadas crudas que se guardan a bordo | B34: 10 | C34: —
A35: Almacenamiento requerido | B35: =B34*B14/1000 -> 1.8265824 | C35: GB
A36: Con 50 % de margen (ECSS) | B36: =B35/0.5 -> 3.6531648 | C36: GB | E36: ET-09
A37: eMMC elegida | B37: 8 | C37: GB
A38: Buffer de imagen: doble cuadro a 16 bit | B38: =2*B5*B6*2/1000000 -> 20.155392 | C38: MB
A39: SDRAM mínima con 50 % de margen | B39: =B38/0.5 -> 40.310784 | C39: MB | E39: ET-08
A40: SDRAM elegida | B40: 64 | C40: MB

Sheet Presup. Cómputo
A1: Presupuesto de procesamiento, memoria y buses (§4.2)
A2: RNF-05 y RNF-06 (ECSS-E-ST-20C §4.2.2.2): uso ≤ 50 % de lo disponible en esta etapa.
A4: Recurso | B4: Uso estimado | C4: Disponible | D4: Unidad | E4: Uso | F4: Verificación | G4: Base de la estimación
A5: OBC — RAM | B5: 150 | C5: 786 | D5: KB | E5: =B5/C5 -> 0.19083969 | F5: =IF(E5<=0.5,"Cumple (≤ 50 %)","NO cumple") -> Cumple (≤ 50 %) | G5: RTOS, pilas, buffers CSP y telemetría; STM32U575 [R21]: 786 KB
A6: OBC — flash de programa | B6: 300 | C6: 2048 | D6: KB | E6: =B6/C6 -> 0.14648438 | F6: =IF(E6<=0.5,"Cumple (≤ 50 %)","NO cumple") -> Cumple (≤ 50 %) | G6: código de vuelo estimado; STM32U575: 2 MB
A7: OBC — carga de CPU | B7: 20 | C7: 100 | D7: % | E7: =B7/C7 -> 0.2 | F7: =IF(E7<=0.5,"Cumple (≤ 50 %)","NO cumple") -> Cumple (≤ 50 %) | G7: EKF de 7 estados a 1 Hz + TT&C + housekeeping en un Cortex-M4F a 80 MHz
A8: OBC — NOR de telemetría | B8: =64*1440*183/1000000+2*0.3 -> 17.46528 | C8: 64 | D8: MB | E8: =B8/C8 -> 0.272895 | F8: =IF(E8<=0.5,"Cumple (≤ 50 %)","NO cumple") -> Cumple (≤ 50 %) | G8: telemetría de 6 meses (64 B/min ≈ 16.9 MB) + 2 imágenes de firmware de ~0.3 MB
A9: PPU — SDRAM | B9: ='Presup. Datos'!B38 -> 20.155392 | C9: ='Presup. Datos'!B40 -> 64 | D9: MB | E9: =B9/C9 -> 0.314928 | F9: =IF(E9<=0.5,"Cumple (≤ 50 %)","NO cumple") -> Cumple (≤ 50 %) | G9: doble cuadro a 16 bit (Presup. Datos)
A10: PPU — eMMC | B10: ='Presup. Datos'!B35 -> 1.8265824 | C10: ='Presup. Datos'!B37 -> 8 | D10: GB | E10: =B10/C10 -> 0.2283228 | F10: =IF(E10<=0.5,"Cumple (≤ 50 %)","NO cumple") -> Cumple (≤ 50 %) | G10: 10 pasadas crudas (Presup. Datos)
A11: Bus CAN entre tarjetas | B11: 19.2 | C11: 450 | D11: kbps | E11: =B11/C11 -> 0.042666667 | F11: =IF(E11<=0.5,"Cumple (≤ 50 %)","NO cumple") -> Cumple (≤ 50 %) | G11: descarga de imagen; CAN 1 Mbps ≈ 450 kbps útiles con tramas de 8 bytes
A13: Los valores "disponible" corresponden a los procesadores de referencia (STM32U575 para el OBC, i.MX RT1170 con SDRAM y eMMC externas para la carga útil); se confirman en P4 (TBD-01).

Sheet Balance Enlace
A1: Balance de enlace UHF, 436 MHz (§10.4)
A2: C/N0 = PIRE − pérdidas − FSPL + G/T − k. Margen = C/N0 − 10·log(R) − Eb/N0 requerido.
A4: Supuesto | B4: Valor | C4: Unidad
A5: Frecuencia | B5: 436 | C5: MHz
A6: Potencia de transmisión del satélite | B6: 0 | C6: dBW
A7: Ganancia de la antena del satélite | B7: 0 | C7: dBi
A8: Pérdida de línea | B8: 1 | C8: dB
A9: Pérdida de polarización | B9: 3 | C9: dB
A10: Atmósfera + centelleo ionosférico | B10: 2 | C10: dB
A11: Pérdida de apuntamiento | B11: 0.5 | C11: dB
A12: Ganancia de la estación (Yagi cruzada) | B12: 14 | C12: dBic
A13: Temperatura de ruido del sistema | B13: 1000 | C13: K
A14: Eb/N0 requerido (GFSK + FEC) | B14: 10 | C14: dB
A15: Constante de Boltzmann | B15: -228.6 | C15: dBW/K/Hz
A16: Potencia del transmisor en tierra | B16: 50 | C16: W
A17: Sensibilidad del receptor del satélite | B17: -122 | C17: dBm @ 5 kbaud
A18: G/T de la estación | B18: =B12-10*LOG10(B13) -> -16 | C18: dB/K
A20: Elevación | B20: Distancia (km) | C20: FSPL (dB) | D20: C/N0 (dBHz) | E20: Margen 9.6 kbps | F20: Margen 19.2 kbps | G20: Margen 38.4 kbps
A21: 10° | B21: 1816 | C21: =20*LOG10(4*PI()*B21*1000/(299792458/($B$5*1000000))) -> 150.41983 | D21: =$B$6+$B$7-$B$8-C21-$B$9-$B$10-$B$11+$B$18-$B$15 -> 55.68017 | E21: =D21-10*LOG10(9600)-$B$14 -> 5.8574578 | F21: =D21-10*LOG10(19200)-$B$14 -> 2.8471578 | G21: =D21-10*LOG10(38400)-$B$14 -> -0.16314213
A22: 30° | B22: 1002 | C22: =20*LOG10(4*PI()*B22*1000/(299792458/($B$5*1000000))) -> 145.25487 | D22: =$B$6+$B$7-$B$8-C22-$B$9-$B$10-$B$11+$B$18-$B$15 -> 60.845133 | E22: =D22-10*LOG10(9600)-$B$14 -> 11.02242 | F22: =D22-10*LOG10(19200)-$B$14 -> 8.0121203 | G22: =D22-10*LOG10(38400)-$B$14 -> 5.0018203
A23: 90° (cenit) | B23: 550 | C23: =20*LOG10(4*PI()*B23*1000/(299792458/($B$5*1000000))) -> 140.04477 | D23: =$B$6+$B$7-$B$8-C23-$B$9-$B$10-$B$11+$B$18-$B$15 -> 66.055233 | E23: =D23-10*LOG10(9600)-$B$14 -> 16.232521 | F23: =D23-10*LOG10(19200)-$B$14 -> 13.222221 | G23: =D23-10*LOG10(38400)-$B$14 -> 10.211921
A25: Enlace ascendente (a 10° de elevación)
A26: Potencia recibida en el satélite | B26: =10*LOG10(B16)+30+B12-2-C21-B9-B10-B8+B7 -> -97.43013 | C26: dBm
A27: Margen sobre la sensibilidad | B27: =B26-B17 -> 24.56987 | C27: dB
A29: Distancias (amarillo) para 550 km de altura; la de 10° es el rango máximo del contacto (orbita.py). Verde = el enlace cierra a esa tasa. El informe usa 19.2 kbps sobre ~15° y 9.6 kbps por debajo; 38.4 kbps no deja margen cerca del horizonte.

Sheet Masa y Volumen
A1: Presupuesto de masa y volumen (§10.5 y §10.6)
A4: Elemento | B4: Masa (g) | D4: Elemento (a lo largo de Z) | E4: Altura (mm)
A5: Estructura 1U ISISPACE, primaria + secundaria [R25] | B5: 200 | D5: Antena UHF ISISPACE guardada (+Z) [R26] | E5: 7
A6: Arnés, conectores y tornillería adicional | B6: 40 | D6: PCB-1 EPS + baterías 18650 acostadas | E6: 25
A7: 4 paneles solares laterales | B7: 160 | D7: PCB-2 OBC/ADCS/COM (transceptor como hija de 6.5 mm) | E7: 15
A8: PCB-1 EPS | B8: 60 | D8: PCB-3 carga útil | E8: 12
A9: Batería 2 × 18650 + soporte | B9: 115 | D9: Óptica f ≈ 30 mm (la rueda va al lado del tubo) | E9: 30
A10: PCB-2 OBC/ADCS/COM | B10: 60 | D10: Total ocupado | E10: =SUM(E5:E9) -> 89
A11: Módulo transceptor UHF | B11: 25 | D11: Altura interior de la estructura ISISPACE [R25] | E11: 98.4
A12: Antena UHF ISISPACE [R26] | B12: 90 | D12: Holgura | E12: =E11-E10 -> 9.4
A13: Rueda de momento | B13: 60
A14: 3 magnetorquers | B14: 23 | D14: La rueda (28 × 28 × 26 mm [R15]) no cabe en la franja de las baterías (25 mm), así que va junto al tubo de la óptica; los magnetorquers planos (3.2 mm) van en las paredes. La antena se cuenta dentro de la estructura (peor caso, TBD-04). El volumen es la restricción más activa del diseño (riesgo R-04).
A15: Sensores de sol | B15: 10
A16: PCB-3 carga útil | B16: 60
A17: Óptica + filtro + montura | B17: 120
A18: Total | B18: =SUM(B5:B17) -> 1023
A19: Margen de madurez | B19: 0.2
A20: Total con margen | B20: =B18*(1+B19) -> 1227.6
A21: Límite del CDS para 1U (g) | B21: 2000
A22: Uso del límite | B22: =B20/B21 -> 0.6138
A23: Verificación RN-02 / RNF-08 | B23: =IF(B20<=B21,"Cumple","NO cumple") -> Cumple
